<?xml version="1.0" encoding="utf-8"?>

<robot name="r2b_description" xmlns:xacro="http://www.ros.org/wiki/xacro">

  <link name='world'/>

  <link
    name="base_link">
    <inertial>
      <origin
        xyz="0.00073068 -0.0010739 0.025055"
        rpy="0 0 0" />
      <mass
        value="0.038209" />
      <inertia
        ixx="1.2081E-05"
        ixy="1.4586E-08"
        ixz="-4.3058E-09"
        iyy="1.2226E-05"
        iyz="-2.1753E-08"
        izz="1.8632E-05" />
    </inertial>
    <visual>
      <origin
        xyz="0 0 0"
        rpy="0 0 0" />
      <geometry>
        <mesh
          filename="package://r2b_description/meshes/base_link.STL" />
      </geometry>
      <material
        name="">
        <color
          rgba="0.69804 0.69804 0.69804 1" />
      </material>
    </visual>
    <collision>
      <origin
        xyz="0 0 0"
        rpy="0 0 0" />
      <geometry>
        <mesh
          filename="package://r2b_description/meshes/base_link.STL" />
      </geometry>
    </collision>
  </link>

  <joint name="fixed" type="fixed">
		<origin xyz="0.0 0.0 0.0" rpy="0.0 0.0 0.0"/>
		<parent link="world"/>
		<child link="base_link"/>
	</joint>

  <link
    name="link_1">
    <inertial>
      <origin
        xyz="0.084852 0.0002295 -0.0020854"
        rpy="3.1416 0 0" />
      <mass
        value="0.016659" />
      <inertia
        ixx="9.6101E-07"
        ixy="-3.0223E-09"
        ixz="5.7382E-08"
        iyy="2.783E-06"
        iyz="7.0089E-10"
        izz="2.4887E-06" />
    </inertial>
    <visual>
      <origin
        xyz="0 0 0"
        rpy="3.1416 0 0" />
      <geometry>
        <mesh
          filename="package://r2b_description/meshes/link_1.STL" />
      </geometry>
      <material
        name="">
        <color
          rgba="0.69804 0.69804 0.69804 1" />
      </material>
    </visual>
    <collision>
      <origin
        xyz="0 0 0"
        rpy="3.1416 0 0" />
      <geometry>
        <mesh
          filename="package://r2b_description/meshes/link_1.STL" />
      </geometry>
    </collision>
  </link>

  <joint
    name="link_1_jnt"
    type="revolute">
    <origin
      xyz="-0.00328 0.01745 0.03878"
      rpy="1.5708 -1.5708 0" />
    <parent
      link="base_link" />
    <child
      link="link_1" />
    <axis
      xyz="0 0 -1" />
    <limit
      lower="-1.5708"
      upper="1.5708"
      effort="5"
      velocity="5" />
    <dynamics
      damping="0.3"
      friction="0.4" />
  </joint>

  <link
    name="link_2">
    <inertial>
      <origin
        xyz="0.03942 -1.3921E-16 -0.0016"
        rpy="0 0 0" />
      <mass
        value="0.0020624" />
      <inertia
        ixx="1.0046E-08"
        ixy="4.8513E-21"
        ixz="1.8495E-20"
        iyy="1.3592E-06"
        iyz="-1.8314E-15"
        izz="1.3662E-06" />
    </inertial>
    <visual>
      <origin
        xyz="0 0 0"
        rpy="0 0 0" />
      <geometry>
        <mesh
          filename="package://r2b_description/meshes/link_2.STL" />
      </geometry>
      <material
        name="">
        <color
          rgba="0.69804 0.69804 0.69804 1" />
      </material>
    </visual>
    <collision>
      <origin
        xyz="0 0 0"
        rpy="0 0 0" />
      <geometry>
        <mesh
          filename="package://r2b_description/meshes/link_2.STL" />
      </geometry>
    </collision>
  </link>

  <joint
    name="link_2_jnt"
    type="revolute">
    <origin
      xyz="0.087773 0.00019421 -0.014"
      rpy="0 0 0" />
    <parent
      link="link_1" />
    <child
      link="link_2" />
    <axis
      xyz="0 0 -1" />
    <limit
      lower="-3.1416"
      upper="3.1416"
      effort="5"
      velocity="5" />
    <dynamics
      damping="0.3"
      friction="0.4" />
  </joint>

  <link name="ee_link">
    <inertial>
      <origin xyz="0 0 0" rpy="0 0 0"/>
      <mass value="0.001"/>
      <inertia ixx="0.0" ixy="0.0" ixz="0.0" iyy="0.0" iyz="0.0" izz="0.0"/>
    </inertial>
  </link>

  <joint
    name="ee_link_jnt"
    type="fixed">
    <origin
      xyz="0.091 0 -0.0016"
      rpy="0 0 0" />
    <parent
      link="link_2" />
    <child
      link="ee_link" />
  </joint>

  <xacro:include filename="$(find r2b_description)/urdf/r2b_gazebo.xacro"/>
  <xacro:revolute_controllers/>

</robot>